<mujoco>
  <body name="arm_1_link" pos="-0.030741 -0.025571 0.010396" quat="0.49999991 -0.50000025 -0.49999975 -0.50000009">
	    <joint name="servo_motor_1" type="hinge" axis="0 0 1" limited="true"
	           range="-0.537 2.2" ref="-0.274016"
	           damping="0.08" frictionloss="0.03" armature="0.002"/>
    <geom name="arm_1_visual_1" type="mesh" mesh="arm_1_mesh_1" material="mat_arm_link" pos="0.006193 -0.058505 0.023577" quat="-0.02102737 -0.01872554 0.70676801 0.70688485" mass="0" contype="0" conaffinity="0"/>
    <geom name="arm_1_visual_2" type="mesh" mesh="arm_1_mesh_2" material="mat_arm_link" pos="0.006193 -0.058505 0.023577" quat="-0.02102737 -0.01872554 0.70676801 0.70688485" mass="0" contype="0" conaffinity="0"/>
    <geom name="arm_1_collision" type="mesh" mesh="arm_1_collision_mesh" material="mat_collision" pos="0.006169 -0.058604 0.023587" quat="0.02108693 -0.02203713 0.70670611 -0.70684947" contype="1" conaffinity="1" density="270.27" group="3"/>
    <site name="arm_1_tip" pos="0.001870 -0.121024 0.043866" size="0.01" rgba="0.9 0.3 0.3 0.7"/>
    <include file="triangle_link.xml"/>
    <include file="arm_2_link.xml"/>
  </body>
</mujoco>
