<mujoco>
  <body name="arm_2_link" pos="0.001870 -0.121024 0.043866" quat="-0.999999999999955 1.73205073e-07 1.73205133e-07 -1.73205073e-07">
    <joint name="arm_2_joint" type="hinge" axis="0 0 1" limited="false" damping="0.08" armature="0.01"/>
    <geom name="arm_2_visual_1" type="mesh" mesh="arm_2_mesh_1" material="mat_arm_link" pos="-0.042409 -0.022317 -0.018784" quat="0.0001129845 -0.77998415 0.62579926 7.131063e-05" mass="0" contype="0" conaffinity="0"/>
    <geom name="arm_2_visual_2" type="mesh" mesh="arm_2_mesh_2" material="mat_arm_link" pos="-0.042409 -0.022317 -0.018784" quat="0.0001129845 -0.77998415 0.62579926 7.131063e-05" mass="0" contype="0" conaffinity="0"/>
    <geom name="arm_2_visual_3" type="mesh" mesh="arm_2_mesh_3" material="mat_arm_link" pos="-0.042409 -0.022317 -0.018784" quat="0.0001129845 -0.77998415 0.62579926 7.131063e-05" mass="0" contype="0" conaffinity="0"/>
    <geom name="arm_2_collision" type="mesh" mesh="arm_2_collision_mesh" material="mat_collision" pos="0.037006 0.006990 -0.020273" quat="0.60566212 -0.60498339 0.36528792 -0.36569554" contype="1" conaffinity="1" density="236.55" group="3"/>
    <site name="arm2_rod3_anchor_a" pos="-0.04563354 -0.03252434 0.00358615" quat="0.70180072 0.00011808 0.71237329 0.00016745" size="0.01" rgba="0.2 0.6 0.9 0.7"/>
    <site name="arm2_rod3_anchor_b" pos="-0.04562949225 -0.0325237773 0.01358614916" quat="0.70180072 0.00011808 0.71237329 0.00016745" size="0.01" rgba="0.2 0.6 0.9 0.7"/>
    <include file="endpoint_bracket_link.xml"/>
    <include file="camera_link.xml"/>
  </body>
</mujoco>
