<mujoco>
  <body name="endpoint_bracket_link" pos="0.105856 0.056109 0.006752" quat="-0.9999999736 3.3797e-07 -4.9827e-05 -0.0002243268">
    <joint name="endpoint_bracket_joint" type="hinge" axis="0 0 1" limited="false" damping="0.05" armature="0.01"/>
    <geom name="endpoint_bracket_visual" type="mesh" mesh="endpoint_bracket_visual_mesh" material="mat_arm_link" pos="0.011018 -0.008561 -0.025835" quat="-0.9999999738459482 3.37810883e-07 -4.93267207e-05 -0.000223326809" mass="0" contype="0" conaffinity="0"/>
    <geom name="endpoint_bracket_collision" type="mesh" mesh="endpoint_bracket_collision_mesh" material="mat_collision" pos="0.010956 -0.008580 -0.026963" quat="-0.9999999735973328 3.37972373e-07 -4.98267203e-05 -0.000224326809" contype="1" conaffinity="1" density="236.55" friction="2 0.1 0.01" solref="0.001 1" solimp="0.95 0.99 0.001" margin="0.002" group="3"/>
    <include file="rod_1_link.xml"/>
    <include file="gripper_link.xml"/>
  </body>
</mujoco>
