<mujoco>
  <body name="right_gripper_1" pos="0.011580 0.000000 0.040763" quat="0.7071068967 -0.0000000000 0.7071066656 0.0000000000">
    <joint name="right_gripper_1_joint" type="hinge" axis="0 0 1" limited="true" range="-1e-06 1e-06"/>
    <geom name="right_gripper_1_visual" type="mesh" mesh="right_gripper_1_visual_mesh" material="mat_arm_link" pos="0.010940 -0.006261 0.000030" quat="0.5970981057 0.6301957095 0.3233663540 0.3765121792" mass="1e-4" contype="0" conaffinity="0"/>

    <body name="right_gripper_2" pos="0.021349 -0.013036 0.000000" quat="-1.0000000000 -0.0000001732 0.0000001732 0.0000001732">
      <joint name="right_gripper_2_joint" type="hinge" axis="0 0 1" limited="true" range="-1e-06 1e-06"/>
      <geom name="right_gripper_2_collision" type="mesh" mesh="right_gripper_2_collision_mesh" material="mat_collision" pos="0.008719 -0.009971 0.000092" quat="0.5376308245 -0.4592964837 -0.5376306488 -0.4592963336" friction="10 2 0.2" condim="6" solref="0.0005 1" solimp="0.999 0.999 0.0001" margin="0.0005" contype="0" conaffinity="0" density="236.55" group="3"/>
      <geom name="right_gripper_2_visual" type="mesh" mesh="right_gripper_2_visual_mesh" material="mat_arm_link" pos="0.003722 -0.006814 0.000278" quat="0.3956872050 -0.5860305446 -0.3956870757 -0.5860303531" mass="1e-4" contype="0" conaffinity="0"/>

      <body name="right_gripper_4" pos="0.004715 -0.020848 -0.000006" quat="-1.0000000000 0.0000001732 0.0000001732 -0.0000001732">
        <joint name="right_gripper_4_joint" type="hinge" axis="0 0 1" limited="true" range="-1e-06 1e-06"/>
        <geom name="right_gripper_4_collision" type="mesh" mesh="right_gripper_4_collision_mesh" material="mat_collision" pos="0.020388 -0.001817 0.000098" quat="0.0888815344 0.7014985647 -0.0888815054 0.7014983354" friction="10 2 0.2" condim="6" solref="0.0005 1" solimp="0.999 0.999 0.0001" margin="0.0005" contype="0" conaffinity="0" density="236.55" group="3"/>
        <geom name="right_gripper_4_visual" type="mesh" mesh="right_gripper_4_visual_mesh" material="mat_arm_link" pos="0.020096 -0.002753 -0.000003" quat="0.1134273906 0.6981743169 -0.1115845443 0.6980227359" mass="1e-4" contype="0" conaffinity="0"/>

        <body name="right_gripper_5" pos="0.038592 -0.010314 0.000002" quat="1.0000000000 0.0000001732 -0.0000001732 0.0000001732">
          <joint name="right_gripper_5_joint" type="hinge" axis="0 0 1" limited="true" range="-1e-06 1e-06"/>
          <geom name="right_gripper_5_collision" type="mesh" mesh="right_gripper_5_collision_mesh" material="mat_collision" pos="0.017968 0.008301 -0.001428" quat="-0.7039054782 -0.0462230231 0.7070751000 0.0492474646" friction="10 2 0.2" condim="6" solref="0.0005 1" solimp="0.999 0.999 0.0001" margin="0.0005" contype="0" conaffinity="0" density="236.55" group="3"/>
          <geom name="right_gripper_5_visual" type="mesh" mesh="right_gripper_5_visual_mesh" material="mat_arm_link" pos="0.017573 0.011847 0.000239" quat="-0.1444811373 0.7001851238 0.1479251314 0.6833623848" mass="1e-4" contype="0" conaffinity="0"/>

          <body name="right_gripper_6" pos="0.005928 0.013307 -0.000000" quat="1.0000000000 -0.0000001732 -0.0000001732 -0.0000001732">
            <joint name="right_gripper_6_joint" type="hinge" axis="0 0 1" limited="true" range="-1e-06 1e-06"/>
            <geom name="right_gripper_6_collision" type="mesh" mesh="right_gripper_6_collision_mesh" material="mat_collision" pos="-0.008213 0.009072 -0.000056" quat="-0.6619393454 0.6618061902 0.2488216831 -0.2488707287" friction="10 2 0.2" condim="6" solref="0.0005 1" solimp="0.999 0.999 0.0001" margin="0.0005" contype="0" conaffinity="0" density="236.55" group="3"/>
            <geom name="right_gripper_6_visual" type="mesh" mesh="right_gripper_6_visual_mesh" material="mat_arm_link" pos="-0.008240 0.009208 -0.000001" quat="-0.6637850563 0.6590045426 0.2562775497 -0.2437708542" mass="1e-4" contype="0" conaffinity="0"/>

            <body name="right_gripper_7" pos="-0.015696 0.017630 -0.000000" quat="-1.0000000000 0.0000001732 0.0000001732 -0.0000001732">
              <joint name="right_gripper_7_joint" type="hinge" axis="0 0 1" limited="true" range="-1e-06 1e-06"/>
              <geom name="right_gripper_7_collision" type="mesh" mesh="right_gripper_7_collision_mesh" material="mat_collision" pos="-0.008798 0.009703 -0.000056" quat="-0.6610971722 0.6611071940 0.2508912940 -0.2508811782" friction="10 2 0.2" condim="6" solref="0.0005 1" solimp="0.999 0.999 0.0001" margin="0.0005" contype="1" conaffinity="1" density="236.55" group="3"/>
              <geom name="right_fingertip_pad" type="sphere" size="0.014" pos="-0.008798 0.009703 -0.000056" friction="12 1 0.05" condim="6" solref="0.0005 1" solimp="0.95 0.99 0.001" margin="0.0003" contype="1" conaffinity="1" mass="1e-4" group="3"/>
              <geom name="right_gripper_7_visual" type="mesh" mesh="right_gripper_7_visual_mesh" material="mat_arm_link" pos="-0.006985 0.007728 -0.000017" quat="-0.6633112578 0.6607673112 0.2534859509 -0.2432069251" mass="1e-4" contype="0" conaffinity="0"/>
            </body>
          </body>
        </body>
      </body>
    </body>
  </body>
</mujoco>
