<mujoco>
  <body name="rod_1_link" pos="0.013458 -0.021307 -0.054097" quat="-0.99994333 1.75039251e-07 1.71351324e-07 0.01064613">
    <joint name="rod_1_joint" type="hinge" axis="0 0 1" limited="false" damping="0.05" armature="0.01"/>
    <geom name="rod_1_visual" type="mesh" mesh="rod_1_visual_mesh" material="mat_arm_link" pos="-0.050750 -0.031179 -0.000002" quat="-0.17729514 0.68451985 0.17729481 0.68451849" mass="0" contype="0" conaffinity="0"/>
    <geom name="rod_1_collision" type="mesh" mesh="rod_1_collision_mesh" material="mat_collision" pos="-0.050842 -0.031213 0" quat="-0.17684451 0.68463560 0.17684727 0.68463505" contype="1" conaffinity="1" density="236.55" group="3"/>
    <site name="rod1_triangle_anchor_a" pos="-0.10708636 -0.06427675 0.0000001778" size="0.01" rgba="0.9 0.5 0.2 0.7"/>
    <site name="rod1_triangle_anchor_b" pos="-0.10708331757 -0.06427613427 0.01000017732" size="0.01" rgba="0.9 0.5 0.2 0.7"/>
  </body>
</mujoco>
