<mujoco>
  <body name="triangle_link" pos="0.002022 -0.121233 -0.007103" quat="0.99218016 3.4586e-07 -1.3106e-07 0.12481396">
    <joint name="triangle_joint" type="hinge" axis="0 0 1" limited="false" damping="0.05"/>
    <geom name="triangle_visual" type="mesh" mesh="triangle_visual_mesh" material="mat_arm_link" pos="-0.014063 -0.018900 0.000005" quat="-0.13464383 -0.69416925 -0.13419076 0.69425711" mass="0" contype="0" conaffinity="0"/>
    <geom name="triangle_collision" type="mesh" mesh="triangle_collision_mesh" material="mat_collision" pos="-0.014028 -0.018759 0.000005" quat="-0.13481909 -0.69413516 -0.13436607 0.69422327" contype="1" conaffinity="1" density="202.75" group="3"/>
    <site name="triangle_rod2_anchor_a" pos="-0.04219347 -0.01836418 0.00360767" size="0.01" rgba="0.5 0.8 0.2 0.7"/>
    <site name="triangle_rod2_anchor_b" pos="-0.04218940803 -0.01836462661 0.01360766917" size="0.01" rgba="0.5 0.8 0.2 0.7"/>
    <site name="triangle_rod1_anchor_a" pos="0.00373738 -0.02883801 0.00363371" size="0.01" rgba="0.8 0.5 0.2 0.7"/>
    <site name="triangle_rod1_anchor_b" pos="0.00374144197 -0.02883845661 0.01363370917" size="0.01" rgba="0.8 0.5 0.2 0.7"/>
  </body>
</mujoco>
